<mujoco model="scene">
  <compiler angle="radian" inertiafromgeom="true"/>
  <option timestep="0.01" gravity="0 0 -9.8100000000000005" integrator="implicitfast" solver="CG"/>
  <default>
    <default class="/"/>
  </default>
  <asset>
    <texture name="//unnamed_texture_0" builtin="gradient" rgb1="0.40000000000000002 0.5 0.59999999999999998" rgb2="0 0 0" width="100" height="100"/>
    <texture name="texgeom" type="cube" builtin="flat" rgb1="0.80000000000000004 0.59999999999999998 0.40000000000000002" rgb2="0.80000000000000004 0.59999999999999998 0.40000000000000002" mark="cross" markrgb="1 1 1" random="0.01" width="127" height="1278"/>
    <texture name="texplane" type="2d" builtin="checker" rgb1="0.13700000000000001 0 0.27500000000000002" rgb2="0.20000000000000001 0 0.39000000000000001" width="100" height="100"/>
    <material name="MatPlane" class="/" texture="texplane" texrepeat="60 60" specular="1" shininess="1" reflectance="0.5"/>
    <material name="geom" class="/" texture="texgeom" texuniform="true"/>
  </asset>
  <worldbody>
    <light name="//unnamed_light_0" class="/" directional="true" castshadow="false" pos="0 0 1.3" dir="0 0 -1.3" cutoff="100" exponent="1" diffuse="1 1 1" specular="0.10000000000000001 0.10000000000000001 0.10000000000000001"/>
    <geom name="table_top" class="/" type="box" conaffinity="1" condim="3" size="0.5 0.5 0.025000000000000001" rgba="0.59999999999999998 0.40000000000000002 0.20000000000000001 1" friction="0.69999999999999996 0.10000000000000001 0.10000000000000001" pos="0 0 0.80000000000000004"/>
    <geom name="table_leg_1" class="/" type="box" conaffinity="1" condim="3" size="0.050000000000000003 0.050000000000000003 0.40000000000000002" rgba="0.5 0.29999999999999999 0.10000000000000001 1" friction="0.69999999999999996 0.10000000000000001 0.10000000000000001" pos="0.45000000000000001 0.45000000000000001 0.40000000000000002"/>
    <geom name="table_leg_2" class="/" type="box" conaffinity="1" condim="3" size="0.050000000000000003 0.050000000000000003 0.40000000000000002" rgba="0.5 0.29999999999999999 0.10000000000000001 1" friction="0.69999999999999996 0.10000000000000001 0.10000000000000001" pos="-0.45000000000000001 0.45000000000000001 0.40000000000000002"/>
    <geom name="table_leg_3" class="/" type="box" conaffinity="1" condim="3" size="0.050000000000000003 0.050000000000000003 0.40000000000000002" rgba="0.5 0.29999999999999999 0.10000000000000001 1" friction="0.69999999999999996 0.10000000000000001 0.10000000000000001" pos="0.45000000000000001 -0.45000000000000001 0.40000000000000002"/>
    <geom name="table_leg_4" class="/" type="box" conaffinity="1" condim="3" size="0.050000000000000003 0.050000000000000003 0.40000000000000002" rgba="0.5 0.29999999999999999 0.10000000000000001 1" friction="0.69999999999999996 0.10000000000000001 0.10000000000000001" pos="-0.45000000000000001 -0.45000000000000001 0.40000000000000002"/>
    <geom name="floor" class="/" type="plane" conaffinity="1" condim="3" size="40 40 40" material="MatPlane" rgba="0.80000000000000004 0.90000000000000002 0.80000000000000004 1" friction="0.69999999999999996 0.10000000000000001 0.10000000000000001" pos="0 0 -0.01"/>
    <site name="target" class="/" type="sphere" rgba="1 0 0 1" size="0.10000000000000001" pos="0 0 0.83500000000000008"/>
    <body name="lynx_base" pos="0 0 0.80000000000000004" quat="1 0 0 0">
      <camera name="top_view" class="/" fovy="45" pos="0 0 3" xyaxes="1 0 0 0 1 0"/>
      <camera name="side_view" class="/" fovy="45" pos="2.5 0 0.5" xyaxes="0 1 0 0 0 1"/>
      <camera name="isometric_view" class="/" fovy="45" pos="1.6000000000000001 1.6000000000000001 1.6000000000000001" xyaxes="-0.70699999999999996 0.70699999999999996 0 -0.40799999999999997 -0.40799999999999997 0.81599999999999995"/>
      <geom name="//unnamed_geom_6" class="/" type="cylinder" size="0.095000000000000001 0.042500000000000003" pos="0 0 0.042500000000000003"/>
      <geom name="//unnamed_geom_7" class="/" type="cylinder" size="0.074999999999999997 0.0071999999999999998" pos="0 0 0.092200000000000004"/>
      <body name="joint1" pos="0 0 0.099400000000000002" quat="1 0 0 0">
        <joint name="joint1_joint" class="/" axis="0 0 1" armature="0.01" damping="100000" frictionloss="9.9999999999999995e-07"/>
        <geom name="lynxg1_joint1" class="/" type="cylinder" size="0.074999999999999997 0.082900000000000001" rgba="0 0 0 1" pos="0 0 0.082900000000000001"/>
        <geom name="lynxg2_joint1" class="/" type="cylinder" size="0.074999999999999997 0.0050000000000000001" pos="0 -0.075000000000000011 0.082900000000000001" quat="0.70710678118654757 0.70710678118654757 0 0"/>
        <body name="joint2" pos="0 -0.080000000000000016 0.082900000000000001" quat="4.329780281177467e-17 4.329780281177467e-17 0.70710678118654757 -0.70710678118654757">
          <joint name="joint2_joint" class="/" axis="0 0 1" armature="0.01" damping="100000" frictionloss="9.9999999999999995e-07"/>
          <geom name="lynxg1_joint2" class="/" type="cylinder" size="0.074999999999999997 0.082900000000000001" rgba="0 0 0 1" pos="0 0 0.082900000000000001"/>
          <geom name="lynxg2_joint2" class="/" type="cylinder" size="0.074999999999999997 0.0050000000000000001" pos="0 -0.075000000000000011 0.082900000000000001" quat="0.70710678118654757 0.70710678118654757 0 0"/>
          <body name="straight_tube" pos="0 -0.080000000000000016 0.082900000000000001" quat="0.70710678118654757 0.70710678118654757 0 0">
            <geom name="lynx_straight_tube" class="/" type="cylinder" size="0.074999999999999997 0.20000000000000001" rgba="1 1 1 1" pos="0 0 0.20000000000000001"/>
            <body name="joint3" pos="0 0 0.40000000000000002" quat="0.70710678118654757 0.70710678118654746 0 0">
              <joint name="joint3_joint" class="/" type="hinge" pos="0 0.074999999999999997 0" axis="0 0 1" armature="0.01" damping="100000" frictionloss="9.9999999999999995e-07"/>
              <geom name="lynxg1_joint3" class="/" type="cylinder" size="0.074999999999999997 0.082900000000000001" rgba="0 0 0 1" pos="0 0.074999999999999997 0"/>
              <geom name="lynxg2_joint3" class="/" type="cylinder" size="0.074999999999999997 0.0050000000000000001" pos="0 0.075000000000000011 0.087900000000000006" quat="1.1102230246251565e-16 1 0 0"/>
              <body name="joint4" pos="0 0.075000000000000011 0.09290000000000001" quat="4.329780281177467e-17 4.3297802811774658e-17 0.70710678118654757 0.70710678118654746">
                <joint name="joint4_joint" class="/" type="hinge" pos="0 0.074999999999999997 0" axis="0 0 1" armature="0.01" damping="100000" frictionloss="9.9999999999999995e-07"/>
                <geom name="lynxg1_joint4" class="/" type="cylinder" size="0.074999999999999997 0.082900000000000001" rgba="0 0 0 1" pos="0 0.074999999999999997 0"/>
                <geom name="lynxg2_joint4" class="/" type="cylinder" size="0.074999999999999997 0.0050000000000000001" pos="0 0.075000000000000011 0.087900000000000006" quat="1.1102230246251565e-16 1 0 0"/>
                <body name="straight_tube2" pos="0 0.075000000000000011 0.09290000000000001" quat="1 0 0 0">
                  <geom name="lynx_straight_tube2" class="/" type="cylinder" size="0.074999999999999997 0.20000000000000001" rgba="1 1 1 1" pos="0 0 0.20000000000000001"/>
                  <body name="joint5" pos="0 0 0.40000000000000002" quat="0.70710678118654757 0.70710678118654746 0 0">
                    <joint name="joint5_joint" class="/" type="hinge" pos="0 0.074999999999999997 0" axis="0 0 1" armature="0.01" damping="100000" frictionloss="9.9999999999999995e-07"/>
                    <geom name="lynxg1_joint5" class="/" type="cylinder" size="0.074999999999999997 0.082900000000000001" rgba="0 0 0 1" pos="0 0.074999999999999997 0"/>
                    <geom name="lynxg2_joint5" class="/" type="cylinder" size="0.074999999999999997 0.0050000000000000001" pos="0 0.075000000000000011 0.087900000000000006" quat="1.1102230246251565e-16 1 0 0"/>
                    <body name="joint6" pos="0 0.075000000000000011 0.09290000000000001" quat="0.70710678118654757 0.70710678118654746 0 0">
                      <joint name="joint6_joint" class="/" type="hinge" pos="0 0.074999999999999997 0" axis="0 0 1" armature="0.01" damping="100000" frictionloss="9.9999999999999995e-07"/>
                      <geom name="lynxg1_joint6" class="/" type="cylinder" size="0.074999999999999997 0.082900000000000001" rgba="0 0 0 1" pos="0 0.074999999999999997 0"/>
                      <geom name="lynxg2_joint6" class="/" type="cylinder" size="0.074999999999999997 0.0050000000000000001" pos="0 0.075000000000000011 0.087900000000000006" quat="1.1102230246251565e-16 1 0 0"/>
                      <body name="ee_cylinder" pos="0 0.075000000000000011 0.09290000000000001" quat="1 0 0 0">
                        <geom name="lynx_ee_cylinder" class="/" type="cylinder" size="0.074999999999999997 0.025000000000000001" rgba="1 1 1 1" pos="0 0 0.025000000000000001"/>
                        <site name="end_effector" class="/" type="sphere" rgba="1 0 0 1" size="0.01" pos="0 0 0.050000000000000003"/>
                      </body>
                    </body>
                  </body>
                </body>
              </body>
            </body>
          </body>
        </body>
      </body>
    </body>
  </worldbody>
  <actuator>
    <position name="//unnamed_actuator_0" class="/" joint="joint1_joint" kp="100000"/>
    <position name="//unnamed_actuator_1" class="/" joint="joint2_joint" kp="100000"/>
    <position name="//unnamed_actuator_2" class="/" joint="joint3_joint" kp="100000"/>
    <position name="//unnamed_actuator_3" class="/" joint="joint4_joint" kp="100000"/>
    <position name="//unnamed_actuator_4" class="/" joint="joint5_joint" kp="100000"/>
    <position name="//unnamed_actuator_5" class="/" joint="joint6_joint" kp="100000"/>
  </actuator>
</mujoco>
